// test('Não deveria passar!', () => {
//   setTimeout(() => {
//     expect(10).toBe(5);
//     console.log('Deveria falhar!');
//   }, 500);
// }); // falso positivo

// test('Não deveria passar!', (done) => {
//   setTimeout(() => {
//     expect(10).toBe(5);
//     console.log('Deveria falhar!');
//     done();
//   }, 500);
// }); // irá falhar com uma mensagem de timeout.

test('Não deveria passar!', (done) => {
  setTimeout(() => {
    try {
      expect(10).toBe(5);
      console.log('Deveria falhar!');
      done();
    } catch (error) {
      done(error); 
    }
  }, 500);
});
// Enquanto o try tenta executar a função no seu escopo com sucesso, o catch "captura" o erro, chamando a callback done